WARNING 2023-03-28 14:37:34,221 django.request Bad Request: /api/instance/31eca28d-22d8-47aa-ba9f-e6ae82510dca/check-redisearch-module-loaded/
WARNING 2023-03-28 14:37:40,977 django.request Bad Request: /api/instance/31eca28d-22d8-47aa-ba9f-e6ae82510dca/redistimeseries/module-info/
ERROR 2023-03-28 14:37:46,156 redisinsight Unknown command error from redis instance:
Traceback (most recent call last):
  File "./redisinsight/utils/__init__.py", line 199, in _wrapped_view
  File "./redisinsight/core/views/decorators.py", line 21, in wrapped_view
  File "./redisinsight/redisai/views.py", line 40, in _wrapped_view
  File "./redisinsight/redisai/views.py", line 85, in models_view
  File "./redisinsight/redisai/services.py", line 181, in list_models
  File "./redisinsight/redisai/services.py", line 157, in _list_models
  File "/usr/local/lib/python3.11/site-packages/redis/client.py", line 901, in execute_command
    return self.parse_response(conn, command_name, **options)
           ^^^^^^^^^^^^^^^^^^^^^^^^^^^^^^^^^^^^^^^^^^^^^^^^^^
  File "/usr/local/lib/python3.11/site-packages/redis/client.py", line 915, in parse_response
    response = connection.read_response()
               ^^^^^^^^^^^^^^^^^^^^^^^^^^
  File "/usr/local/lib/python3.11/site-packages/redis/connection.py", line 756, in read_response
    raise response
redis.exceptions.ResponseError: unknown command 'AI._MODELSCAN', with args beginning with: 
ERROR 2023-03-28 14:37:46,170 redisinsight Unknown command error from redis instance:
Traceback (most recent call last):
  File "./redisinsight/utils/__init__.py", line 199, in _wrapped_view
  File "./redisinsight/core/views/decorators.py", line 21, in wrapped_view
  File "./redisinsight/redisai/views.py", line 40, in _wrapped_view
  File "./redisinsight/redisai/views.py", line 224, in scripts_view
  File "./redisinsight/redisai/services.py", line 206, in list_scripts
  File "./redisinsight/redisai/services.py", line 185, in _list_scripts
  File "/usr/local/lib/python3.11/site-packages/redis/client.py", line 901, in execute_command
    return self.parse_response(conn, command_name, **options)
           ^^^^^^^^^^^^^^^^^^^^^^^^^^^^^^^^^^^^^^^^^^^^^^^^^^
  File "/usr/local/lib/python3.11/site-packages/redis/client.py", line 915, in parse_response
    response = connection.read_response()
               ^^^^^^^^^^^^^^^^^^^^^^^^^^
  File "/usr/local/lib/python3.11/site-packages/redis/connection.py", line 756, in read_response
    raise response
redis.exceptions.ResponseError: unknown command 'AI._SCRIPTSCAN', with args beginning with: 
ERROR 2023-03-28 14:37:46,187 django.request Unknown Status Code: /api/instance/31eca28d-22d8-47aa-ba9f-e6ae82510dca/redisai/models/
ERROR 2023-03-28 14:37:46,189 django.request Unknown Status Code: /api/instance/31eca28d-22d8-47aa-ba9f-e6ae82510dca/redisai/scripts/
