WARNING 2022-03-18 13:43:28,173 django.request Bad Request: /api/instance/31eca28d-22d8-47aa-ba9f-e6ae82510dca/check-redisearch-module-loaded/
WARNING 2022-03-18 13:43:29,122 django.request Bad Request: /api/instance/31eca28d-22d8-47aa-ba9f-e6ae82510dca/redistimeseries/module-info/
ERROR 2022-03-18 13:43:29,854 redisinsight Unknown command error from redis instance:
Traceback (most recent call last):
  File "./redisinsight/utils/__init__.py", line 199, in _wrapped_view
  File "./redisinsight/core/views/decorators.py", line 21, in wrapped_view
  File "./redisinsight/redisai/views.py", line 40, in _wrapped_view
  File "./redisinsight/redisai/views.py", line 224, in scripts_view
  File "./redisinsight/redisai/services.py", line 205, in list_scripts
  File "./redisinsight/redisai/services.py", line 184, in _list_scripts
  File "/usr/local/lib/python3.6/site-packages/redis/client.py", line 901, in execute_command
    return self.parse_response(conn, command_name, **options)
  File "/usr/local/lib/python3.6/site-packages/redis/client.py", line 915, in parse_response
    response = connection.read_response()
  File "/usr/local/lib/python3.6/site-packages/redis/connection.py", line 756, in read_response
    raise response
redis.exceptions.ResponseError: unknown command `AI._SCRIPTSCAN`, with args beginning with: 
ERROR 2022-03-18 13:43:29,856 redisinsight Unknown command error from redis instance:
Traceback (most recent call last):
  File "./redisinsight/utils/__init__.py", line 199, in _wrapped_view
  File "./redisinsight/core/views/decorators.py", line 21, in wrapped_view
  File "./redisinsight/redisai/views.py", line 40, in _wrapped_view
  File "./redisinsight/redisai/views.py", line 85, in models_view
  File "./redisinsight/redisai/services.py", line 180, in list_models
  File "./redisinsight/redisai/services.py", line 156, in _list_models
  File "/usr/local/lib/python3.6/site-packages/redis/client.py", line 901, in execute_command
    return self.parse_response(conn, command_name, **options)
  File "/usr/local/lib/python3.6/site-packages/redis/client.py", line 915, in parse_response
    response = connection.read_response()
  File "/usr/local/lib/python3.6/site-packages/redis/connection.py", line 756, in read_response
    raise response
redis.exceptions.ResponseError: unknown command `AI._MODELSCAN`, with args beginning with: 
ERROR 2022-03-18 13:43:29,861 django.request Unknown Status Code: /api/instance/31eca28d-22d8-47aa-ba9f-e6ae82510dca/redisai/scripts/
ERROR 2022-03-18 13:43:29,866 django.request Unknown Status Code: /api/instance/31eca28d-22d8-47aa-ba9f-e6ae82510dca/redisai/models/
WARNING 2022-03-18 13:43:31,047 django.request Bad Request: /api/instance/31eca28d-22d8-47aa-ba9f-e6ae82510dca/redisgraph/check-module-loaded/
WARNING 2022-03-18 13:43:33,212 django.request Bad Request: /api/instance/31eca28d-22d8-47aa-ba9f-e6ae82510dca/redisgraph/check-module-loaded/
ERROR 2022-03-18 13:44:05,163 redisinsight Unknown command error from redis instance:
Traceback (most recent call last):
  File "./redisinsight/utils/__init__.py", line 199, in _wrapped_view
  File "./redisinsight/core/views/decorators.py", line 21, in wrapped_view
  File "./redisinsight/redisai/views.py", line 40, in _wrapped_view
  File "./redisinsight/redisai/views.py", line 224, in scripts_view
  File "./redisinsight/redisai/services.py", line 205, in list_scripts
  File "./redisinsight/redisai/services.py", line 184, in _list_scripts
  File "/usr/local/lib/python3.6/site-packages/redis/client.py", line 901, in execute_command
    return self.parse_response(conn, command_name, **options)
  File "/usr/local/lib/python3.6/site-packages/redis/client.py", line 915, in parse_response
    response = connection.read_response()
  File "/usr/local/lib/python3.6/site-packages/redis/connection.py", line 756, in read_response
    raise response
redis.exceptions.ResponseError: unknown command `AI._SCRIPTSCAN`, with args beginning with: 
ERROR 2022-03-18 13:44:05,169 redisinsight Unknown command error from redis instance:
Traceback (most recent call last):
  File "./redisinsight/utils/__init__.py", line 199, in _wrapped_view
  File "./redisinsight/core/views/decorators.py", line 21, in wrapped_view
  File "./redisinsight/redisai/views.py", line 40, in _wrapped_view
  File "./redisinsight/redisai/views.py", line 85, in models_view
  File "./redisinsight/redisai/services.py", line 180, in list_models
  File "./redisinsight/redisai/services.py", line 156, in _list_models
  File "/usr/local/lib/python3.6/site-packages/redis/client.py", line 901, in execute_command
    return self.parse_response(conn, command_name, **options)
  File "/usr/local/lib/python3.6/site-packages/redis/client.py", line 915, in parse_response
    response = connection.read_response()
  File "/usr/local/lib/python3.6/site-packages/redis/connection.py", line 756, in read_response
    raise response
redis.exceptions.ResponseError: unknown command `AI._MODELSCAN`, with args beginning with: 
ERROR 2022-03-18 13:44:05,165 django.request Unknown Status Code: /api/instance/31eca28d-22d8-47aa-ba9f-e6ae82510dca/redisai/scripts/
ERROR 2022-03-18 13:44:05,179 django.request Unknown Status Code: /api/instance/31eca28d-22d8-47aa-ba9f-e6ae82510dca/redisai/models/
WARNING 2022-03-18 13:44:16,396 django.request Bad Request: /api/instance/31eca28d-22d8-47aa-ba9f-e6ae82510dca/redistimeseries/module-info/
WARNING 2022-03-18 13:44:21,099 django.request Bad Request: /api/instance/31eca28d-22d8-47aa-ba9f-e6ae82510dca/check-redisearch-module-loaded/
